<mujoco model="Simplified UAV">
    <compiler inertiafromgeom="true"/>
    <option gravity="0 0 -9.81" iterations="50" integrator="Euler" density="1.225" viscosity="1.8e-5"/>

    <default>
        <joint damping="0.01"/>
        <geom friction="1 0.5 0.5" density="1000" margin="0.01"/>
        <motor ctrlrange="0.0 10.0"/>
    </default>

    <worldbody>
        <body name="drone" pos="0 0 0">
            <freejoint/>
            <site name="drone" pos="0 0 0" size="0.05" rgba="0 1 0 1"/>
            <geom name="drone" type="box" size="0.1 0.1 0.1" mass="1"/>

            <body name="arms" pos="0 0 0.1" euler="0 0 45">
                <!-- Arm 1 -->
                <body name="arm1" pos="0.15 0 0">
                    <geom type="box" size="0.25 0.0125 0.0125" mass="0.1"/>
                    <body name="prop1" pos="0.25 0 0">
                        <joint name="prop1_joint" type="hinge" axis="0 0 1"/>
                        <geom type="cylinder" size="0.1 0.005" mass="0.05"/>
                        <site name="prop1_thrust" pos="0 0 -0.025"/>
                    </body>
                </body>

                <!-- Arm 2 -->
                <body name="arm2" pos="-0.15 0 0">
                    <geom type="box" size="0.25 0.0125 0.0125" mass="0.1"/>
                    <body name="prop2" pos="-0.25 0 0">
                        <joint name="prop2_joint" type="hinge" axis="0 0 1"/>
                        <geom type="cylinder" size="0.1 0.005" mass="0.05"/>
                        <site name="prop2_thrust" pos="0 0 -0.025"/>
                    </body>
                </body>

                <!-- Arm 3 -->
                <body name="arm3" pos="0 0.15 0">
                    <geom type="box" size="0.25 0.0125 0.0125" mass="0.1" euler="0 0 90"/>
                    <body name="prop3" pos="0 0.25 0">
                        <joint name="prop3_joint" type="hinge" axis="0 0 1"/>
                        <geom type="cylinder" size="0.1 0.005" mass="0.05"/>
                        <site name="prop3_thrust" pos="0 0 -0.025"/>
                    </body>
                </body>

                <!-- Arm 4 -->
                <body name="arm4" pos="0 -0.15 0">
                    <geom type="box" size="0.25 0.0125 0.0125" mass="0.1" euler="0 0 90"/>
                    <body name="prop4" pos="0 -0.25 0">
                        <joint name="prop4_joint" type="hinge" axis="0 0 1"/>
                        <geom type="cylinder" size="0.1 0.005" mass="0.05"/>
                        <site name="prop4_thrust" pos="0 0 -0.025"/>
                    </body>
                </body>
            </body>

            <!-- Front Stereo Cameras -->
            <camera name="camera_left" pos="0.05 0.05 0" zaxis="0 0 -1" fovy="60"/>
            <camera name="camera_right" pos="0.05 -0.05 0" zaxis="0 0 -1" fovy="60"/>
        </body>
    </worldbody>

    <actuator>
        <motor name="motor1" site="prop1_thrust" gear="0 0 10 0 0 -1"/>
        <motor name="motor2" site="prop2_thrust" gear="0 0 10 0 0 -1"/>
        <motor name="motor3" site="prop3_thrust" gear="0 0 10 0 0 1"/>
        <motor name="motor4" site="prop4_thrust" gear="0 0 10 0 0 1"/>
    </actuator>

    <sensor>
        <accelerometer name="imu_accel" site="drone" noise="0.01"/>
        <gyro name="imu_gyro" site="drone" noise="0.005"/>
        <framequat name="imu_orientation" objtype="body" objname="drone"/>
    </sensor>
</mujoco>
