<mujoco model="mini-drone-a-2">
  <!-- Compiler settings to automatically compute inertia from geometry and set mujoco_models directory -->
  <compiler inertiafromgeom="true" assetdir="../assets"/>

  <!-- Simulation options including timestep, gravity, solver iterations, integration method, air density, and air viscosity -->
  <option gravity="0 0 -9.81" iterations="50" integrator="Euler" density="1.225" viscosity="1.8e-5"/>

  <!-- Asset definitions for drone components -->
  <asset>
    <!-- Mesh for the drone body -->
    <mesh name="frame_2" file="frame.stl"/>
    <!-- Mesh for clockwise rotating propellers -->
    <mesh name="cwprop_2" file="cwprop.stl"/>
    <!-- Mesh for counter-clockwise rotating propellers -->
    <mesh name="ccwprop_2" file="ccwprop.stl"/>
  </asset>

  <!-- Default properties for joints, geometries, and motors -->
  <default>
    <!-- Joint properties: low damping to allow free rotation -->
    <joint damping="0.01"/>
    <!-- Geometric properties: friction, density, and collision margin -->
    <geom friction="1 0.5 0.5" density="1000" margin="0.01"/>
    <!-- Motor properties: control range -->
    <motor ctrlrange="0.0 1.0"/>
  </default>

  <worldbody>
    <body name="drone_2" pos="-1.4012585384440734 1.0180739209102547 .25">
      <!-- Free joint for models body to allow free movement in the environment -->
      <freejoint name="drone_2_free_joint"/>
      <inertial pos="0 0 0" mass="0.1"/>
      <site name="drone_2_sensor_site" pos="0 0 0"/>
      <geom name="drone_2_mesh" type="mesh" rgba="0.615686 0.811765 0.929412 1" mesh="frame_2" contype="0" conaffinity="0"/>

      <!-- Main collision box for the drone -->
      <geom name="drone_2_collision_1" type="box" size="0.085 0.085 0.01" rgba="0 0 0 0.2" contype="1" conaffinity="1"/>
      <!-- Additional collision box for the drone -->
      <geom name="drone_2_collision_2" type="box" pos="0 0 -0.02" size="0.015 0.085 0.015" rgba="0 0 0 0.2" contype="1" conaffinity="1"/>

      <!-- Propeller bodies and their visuals -->
      <!-- Clockwise rotating propellers -->
      <body name="front_right_prop_2" pos="0.05 -0.05 0">
        <inertial pos="0 0 -0.00580526" quat="0.5 0.5 -0.5 0.5" mass="0.01"/>
        <site name="front_right_prop_2" pos="0 0 -0.01"/>
        <joint name="front_right_prop_2" pos="0 0 0" axis="0 0 1" limited="false"/>
        <geom name="front_right_prop_2" pos="0 0 -0.005" type="mesh" rgba="0.615686 0.811765 0.929412 1" mesh="cwprop_2"/>
      </body>
      <body name="back_left_prop_2" pos="-0.05 0.05 0">
        <inertial pos="0 0 -0.00580526" quat="0.5 0.5 -0.5 0.5" mass="0.01"/>
        <site name="back_left_prop_2" pos="0 0 -0.01"/>
        <joint name="back_left_prop_2" pos="0 0 0" axis="0 0 1" limited="false"/>
        <geom name="back_left_front_2" pos="0 0 -0.005" type="mesh" rgba="0.615686 0.811765 0.929412 1" mesh="cwprop_2"/>
      </body>
      <!-- Counter-clockwise rotating propellers -->
      <body name="front_left_prop_2" pos="0.05 0.05 0">
        <inertial pos="0 0 -0.00580545" quat="0.5 0.5 -0.5 0.5" mass="0.01"/>
        <site name="front_left_prop_2" pos="0 0 -0.01"/>
        <joint name="front_left_prop_2" pos="0 0 0" axis="0 0 1" limited="false"/>
        <geom name="front_left_prop_2" pos="0 0 -0.005" type="mesh" rgba="0.615686 0.811765 0.929412 1" mesh="ccwprop_2"/>
      </body>
      <body name="back_right_prop_2" pos="-0.05 -0.05 0">
        <inertial pos="0 0 -0.00580545" quat="0.5 0.5 -0.5 0.5" mass="0.01"/>
        <site name="back_right_prop_2" pos="0 0 -0.01"/>
        <joint name="back_right_prop_2" pos="0 0 0" axis="0 0 1" limited="false"/>
        <geom name="back_right_prop_2" pos="0 0 -0.005" type="mesh" rgba="0.615686 0.811765 0.929412 1" mesh="ccwprop_2"/>
      </body>

      <site name="bullet_spawn_position_2" pos="0.08 0 -0.015" size="0.01" rgba="1 1 1 .2"/>

      <!-- Cameras (2 stereo, 1 normal) -->
      <camera name="camera2" pos="0.1 0 0" xyaxes="0 -1 0 0 0 1" fovy="60" mode="fixed"/>
      <camera name="camera2_left" pos="0.1 0.025 0" xyaxes="0 -1 0 0 0 1" fovy="60" mode="fixed"/>
      <camera name="camera2_right" pos="0.1 -0.025 0" xyaxes="0 -1 0 0 0 1" fovy="60" mode="fixed"/>
    </body>
    <body name="bullet_2" pos="0 0 0">
      <freejoint name="bullet_2"/>
      <geom name="bullet_2" type="sphere" size="0.01" rgba="0 0 0 0" contype="0" conaffinity="0"/>
    </body>
  </worldbody>

  <!-- Actuator definitions for controlling drone propellers -->
  <actuator>
    <motor name="front_left_2" site="front_left_prop_2" ctrllimited="true" ctrlrange="0.0 1.0" gear="0 0 10 0 0 1"/>
    <motor name="back_right_2" site="back_right_prop_2" ctrllimited="true" ctrlrange="0.0 1.0" gear="0 0 10 0 0 1"/>
    <motor name="front_right_2" site="front_right_prop_2" ctrllimited="true" ctrlrange="0.0 1.0" gear="0 0 10 0 0 -1"/>
    <motor name="back_left_2" site="back_left_prop_2" ctrllimited="true" ctrlrange="0.0 1.0" gear="0 0 10 0 0 -1"/>
  </actuator>

  <!-- Sensor definitions for the drone-->
  <sensor>
    <accelerometer name="accelerometer2" site="drone_2_sensor_site" noise="0.1" cutoff="10"/>
    <gyro name="gyro2" site="drone_2_sensor_site" noise="0.1" cutoff="10"/>
  </sensor>
</mujoco>
